Workbook

Sheet Read me
A1: Literature map: urban, digital and urban–digital research
A2: Stage 2 build, 2026-10-08. 7666 deduplicated records, of which 388 come only from the supplementary query set and 919 are repository-only. Records per primary theme: A1: 170, A2: 243, A3: 170, A4: 158, A5: 166, A6: 205, A7: 185, A8: 274, A9: 211, A10: 163, A11: 165, A12: 164, A13: 182, A14: 189, A15: 155, A16: 211, B1: 167, B2: 158, B3: 147, B4: 184, B5: 199, B6: 187, B7: 177, B8: 217, B9: 179, B10: 173, B11: 196, B12: 146, B13: 151, B14: 153, C1: 194, C2: 181, C3: 88, C4: 123, C5: 115, C6: 112, C7: 120, C8: 121, C9: 186, C10: 144, C11: 100, C12: 92, C13: 153, C14: 103, C15: 85, C16: 126, C17: 118, C18: 60.
A3: What this is
A4: A representative, reproducible map — not a census — of three domains (A urban, B digital society, C urban × digital), 48 themes. Every record comes from an OpenAlex API response; raw responses are cached in data/raw/ of the repository. See BRIEF.md, queries.yaml, PROGRESS.md and scripts/.
A5: Tabs
A6: Records — one row per work (schema below). Gap matrix — live COUNTIFS of theme × region, theme × method, theme × period (supplementary-only records excluded). Growth — OpenAlex-wide counts per theme, precision-adjusted and normalised (Stage 3 input). Emerging terms — Stage 3. Landmarks by theme — records from the 'landmarks' slice, repository-only records excluded. India subset — India-flagged records. Shortlist — records touching current leads.
A7: How records were found
A8: For each theme, 2–6 queries (queries.yaml) run against the OpenAlex API in exact-phrase mode over title and abstract (Stage 1 pilot slices: title, abstract and keywords), in three slices: landmarks (the theme's queries OR-ed, top 100 by citations; page 2 where fewer than 25 survived), recent (2022–2026, one search per query string, top 15–25 by relevance), India/South Asia (each query AND South Asian place names, top 15–25 by relevance). A supplementary query set (S1–S7: railway stations, waiting, night-time transit, fare integration/NCMC, rail-led urbanism, elevated rail, Haryana secondary cities) was searched separately; records found only there are tagged Supplementary = Y and given the query's home theme.
A9: Screening
A10: Rule-based on title + abstract (rules v3, queries.yaml header): the theme's core concept in the title or twice in the abstract, plus its context terms (for C themes the urban context, or a named city, is required). Borderline cases (single mention named by a keyword tag, flagged technical/biomedical terms with the core in the title, stub abstracts) were decided by hand (data/screening/manual_review.csv). Records whose OpenAlex primary-topic field is biomedical or natural-science are excluded unless kept by hand. Book reviews, errata, paratext, editorials, datasets and retracted works are excluded. A work is assigned the primary theme with the strongest match among the themes whose searches found it. Deduplicated by DOI, then by normalised title.
A11: Columns that are inferred automatically (check before citing)
A12: Places studied / Region: place names matched in title + abstract (not author affiliations). Region buckets: Global North (Europe, North America, Australia, NZ, Russia), China & East Asia, South Asia, Southeast Asia (incl. Pacific islands), Africa (incl. North Africa), Latin America (incl. Caribbean), Middle East (incl. Central Asia and Caucasus); two or more buckets = Multi-region; none = Not place-specific. India / Delhi-NCR / Haryana flags: same matching. Method: keyword cues in the abstract; 'unclear' when there is no abstract or no cue. Landmark flag: found in a landmarks slice and not repository-only. Repository-only: every merged version sits only in a repository or preprint server (Zenodo, SSRN, arXiv, institutional repositories). C4 orientation: critical vs technical (keyword cues). Emerging flag (provisional): published 2022+ with FWCI ≥ 1.5. One-line summary and Stated gaps: sentences copied from the abstract, marked 'auto:'. Screening confidence: high = rule-included with the core concept and context; medium = rule-included via other routes or kept by hand; low = no abstract.
... A16: Supplementary / Supplementary query = found only by / also by the supplementary query set; Found in = theme:slice combinations that returned the work ('<-X' marks a work moved by hand from theme X); Duplicates merged = other OpenAlex IDs folded into this record; FWCI = OpenAlex field-weighted citation impact.

Sheet Records
A1: ID | B1: Title | C1: Year | D1: Authors | E1: Venue | F1: Document type | G1: DOI | H1: OpenAlex ID | I1: Link | J1: Open-access link | K1: Cited-by count | L1: Domain | M1: Primary theme | N1: Secondary theme | O1: Places studied | P1: Region | Q1: India flag | R1: Delhi/NCR flag | S1: Haryana flag | T1: Method | U1: Landmark flag | V1: Emerging flag | W1: One-line summary | X1: Stated gaps | Y1: Shortlist tag | Z1: Screening confidence | AA1: Repository-only | AB1: Supplementary | AC1: Supplementary query | AD1: C4 orientation | AE1: Found in | AF1: Duplicates merged | AG1: FWCI
A2: LM00001 | B2: From Managerialism to Entrepreneurialism: The Transformation in Urban Governance in Late Capitalism | C2: 1989 | D2: David Harvey | E2: Geografiska Annaler Series B Human Geography | F2: article | G2: 10.1080/04353684.1989.11879583 | H2: W2069072514 | I2: https://doi.org/10.1080/04353684.1989.11879583 | K2: 4713 | L2: A | M2: A1 | P2: Not place-specific | T2: unclear | U2: Y | W2: auto: This paper explores the context of this shift from managerialism to entrepreneurialism in urban governance and seeks to show how mechanisms of inter-urban competition shape outcomes and generate macroeconomic consequences. | Z2: high | AE2: A1:landmarks | AF2: W4244456534 | AG2: 65.4685
A3: LM00002 | B3: New State Spaces | C3: 2004 | D3: Neil Brenner | E3: Oxford University Press eBooks | F3: book | G3: 10.1093/acprof:oso/9780199270057.001.0001 | H3: W2477465903 | I3: https://doi.org/10.1093/acprof:oso/9780199270057.001.0001 | K3: 2295 | L3: A | M3: A1 | O3: Europe | P3: Global North | T3: qualitative | U3: Y | W3: auto: This book develops a new interpretation of the transformation of statehood under contemporary globalizing capitalism. | Z3: medium | AE3: A1:landmarks | AG3: 64.4303
A4: LM00003 | B4: THE DANGERS OF DECENTRALIZATION | C4: 1995 | D4: Rémy Prud’homme | E4: The World Bank Research Observer | F4: article | G4: 10.1093/wbro/10.2.201 | H4: W2124222250 | I4: https://doi.org/10.1093/wbro/10.2.201 | K4: 1897 | L4: A | M4: A1 | P4: Not place-specific | T4: conceptual | U4: Y | W4: auto: This article looks at some of the negative effects of decentralization in the hope that a better understanding of its dangers will contribute to a wiser application of potentially desirable decentralization programs. | Z4: medium | AE4: A1:landmarks | AG4: 112.1795
A5: LM00004 | B5: New State Spaces: Urban Governance and the Rescaling of Statehood | C5: 2004 | D5: Neil Brenner | E5: OUP Catalogue | F5: article | H5: W1513313904 | I5: https://ideas.repec.org/b/oxp/obooks/9780199270064.html | K5: 1885 | L5: A | M5: A1 | P5: Not place-specific | T5: conceptual | U5: Y | W5: auto: Introduction: Cities, States, and the 'Explosion of Spaces' 2. | Z5: high | AE5: A1:landmarks | AG5: 219.8337
A6: LM00005 | B6: Liberalism, Neoliberalism, and Urban Governance: A State–Theoretical Perspective | C6: 2002 | D6: Bob Jessop | E6: Antipode | F6: article | G6: 10.1111/1467-8330.00250 | H6: W2095842624 | I6: https://doi.org/10.1111/1467-8330.00250 | K6: 1460 | L6: A | M6: A1 | P6: Not place-specific | T6: conceptual | U6: Y | W6: auto: This paper discusses the recurrence and the recurrent limitations of liberalism as a general discourse, strategy, and regime. | X6: auto: This paper discusses the recurrence and the recurrent limitations of liberalism as a general discourse, strategy, and regime. | Z6: high | AE6: A1:landmarks | AG6: 100.4158
A7: LM00006 | B7: Globalisation as Reterritorialisation: The Re-scaling of Urban Governance in the European Union | C7: 1999 | D7: Neil Brenner | E7: Urban Studies | F7: article | G7: 10.1080/0042098993466 | H7: W2128580910 | I7: https://doi.org/10.1080/0042098993466 | K7: 1134 | L7: A | M7: A1 | O7: Europe; European | P7: Global North | T7: conceptual | U7: Y | W7: auto: This article argues that processes of reterritorialisation—the reconfiguration and re-scaling of forms of territorial organisation such as cities and states—constitute an intrinsic moment of the current round of globalisation. | Z7: high | AE7: A1:landmarks | AG7: 133.6439
A8: LM00007 | B8: Spaces of Neoliberalism | C8: 2002 | D8: Neil 1969- Brenner; Nik Theodore | E8: Wiley eBooks | F8: book | G8: 10.1002/9781444397499 | H8: W245352281 | I8: https://doi.org/10.1002/9781444397499 | K8: 1059 | L8: A | M8: A1 | O8: Canada; Chicago; Europe; Manchester; New York; Toronto; United Kingdom | P8: Global North | T8: conceptual | U8: Y | W8: auto: From the 'New Localisma to the Spaces of Neoliberalism: Neil Brenner (New York University) & Nik Theodore (University of Illinois at Chicago). | Z8: medium | AE8: A1:landmarks | AG8: 19.2653
A9: LM00008 | B9: The Political Economy of Democratic Decentralization | C9: 1999 | D9: James Manor | E9: World Bank, Washington, DC eBooks | F9: book | G9: 10.1596/0-8213-4470-6 | H9: W1494416504 | I9: https://doi.org/10.1596/0-8213-4470-6 | K9: 967 | L9: A | M9: A1 | N9: A7 | O9: Africa; African; Bangladesh; Brazil; Central AsiaJournal; China; Ethiopia; Ghana; India; Indonesia; Italy; Lagos; Malawi; Nigeria; Norway; Pakistan; Sierra Leone; South Africa; South AsiaInternational; South Asian; South Korea; Southeast AsiaEnvironment; Thailand; United Kingdom; United States; Uruguay; West Bengal; Zambia | P9: Multi-region | Q9: Y | T9: review | U9: Y | W9: auto: No AccessDirections in Development - General1 Feb 2013The Political Economy of Democratic DecentralizationAuthors/Editors: James ManorJames Manorhttps://doi.org/10.1596/0-8213-4470-6SectionsAboutPDF (0.4 MB) ToolsAdd to favoritesDownload CitationsTrack Citations ShareFacebookTwitterLinked In Abst… | X9: auto: This report examines the origins and implications decentralization from a political economy perspective, with a focus on its promise and limitations. | The experience of commune councils in CambodiaAsia Pacific Journal of Public Administration, Vol.40, No.227 June 2018The Trap of Neo-patrimonialism: Social Accountability and Good Governance in CambodiaAsian Studies Review, Vol.42, No.117 January 2018The impact of central-local inter-governmental relations on cultural democracy's developmentAs… | Z9: high | AE9: A1:landmarks; A7:landmarks | AG9: 27.3527
A10: LM00009 | B10: Decentralized Authoritarianism in China | C10: 2008 | D10: Pierre F. Landry | E10: Cambridge University Press eBooks | F10: book | G10: 10.1017/cbo9780511510243 | H10: W1591209570 | I10: https://doi.org/10.1017/cbo9780511510243 | K10: 847 | L10: A | M10: A1 | O10: China | P10: China & East Asia | T10: conceptual | U10: Y | W10: auto: China, like many authoritarian regimes, struggles with the tension between the need to foster economic development by empowering local officials and the regime's imperative to control them politically. | Z10: high | AE10: A1:landmarks | AG10: 29.1742
A11: LM00010 | B11: An inconvenient cost: The effects of climate change on municipal bonds | C11: 2019 | D11: Marcus Painter | E11: Journal of Financial Economics | F11: article | G11: 10.1016/j.jfineco.2019.06.006 | H11: W2952070778 | I11: https://doi.org/10.1016/j.jfineco.2019.06.006 | K11: 823 | L11: A | M11: A1 | P11: Not place-specific | T11: unclear | U11: Y | Z11: low | AE11: A1:landmarks | AG11: 58.2588
A12: LM00011 | B12: Urban Economics and Real Estate Markets | C12: 1995 | D12: Denise DiPasquale; William C. Wheaton | F12: article | H12: W1508404391 | I12: https://bvbr.bib-bvb.de:443/F?func=service&doc_library=BVB01&local_base=BVB01&doc_number=007702443&sequence=000001&line_number=0001&func_code=DB_RECORDS&service_type=MEDIA | K12: 785 | L12: A | M12: A1 | P12: Not place-specific | T12: quantitative | U12: Y | W12: auto: INTRODUCTION TO REAL ESTATE MARKETS. 1. | Z12: high | AE12: A1:landmarks | AG12: 29.0192
A13: LM00012 | B13: Roads, Railroads, and Decentralization of Chinese Cities | C13: 2017 | D13: Nathaniel Brandt Baum-Snow; Loren Brandt; J. Vernon Henderson; Matthew A. Turner; Qinghua Zhang | E13: The Review of Economics and Statistics | F13: article | G13: 10.1162/rest_a_00660 | H13: W2168707163 | I13: https://doi.org/10.1162/rest_a_00660 | J13: https://direct.mit.edu/rest/article-pdf/99/3/435/1918446/rest_a_00660.pdf | K13: 761 | L13: A | M13: A1 | O13: China | P13: China & East Asia | T13: unclear | U13: Y | W13: auto: We investigate how urban railroad and highway configurations have influenced urban form in Chinese cities since 1990. | Z13: medium | AE13: A1:landmarks | AG13: 82.4858
A14: LM00013 | B14: Building Institutional Capacity through Collaborative Approaches to Urban Planning | C14: 1998 | D14: Patsy Healey | E14: Environment and Planning A Economy and Space | F14: article | G14: 10.1068/a301531 | H14: W1983137693 | I14: https://doi.org/10.1068/a301531 | K14: 704 | L14: A | M14: A1 | O14: Europe; United Kingdom | P14: Global North | T14: conceptual | U14: Y | W14: auto: I argue that a key element of such capacity lies in the quality of local policy cultures. | X14: auto: Others are fragmented, lack the connections to sources of power and knowledge, and the mobilisation capacity, to organise to make a difference. | Z14: medium | AE14: A1:landmarks | AG14: 63.5545
A15: LM00014 | B15: Rethinking Decentralization in Developing Countries | C15: 1998 | D15: Jennie I. Litvack; Junaid Aḥmad; Richard Miller Bird | E15: World Bank, Washington, DC eBooks | F15: book | G15: 10.1596/0-8213-4350-5 | H15: W1230600452 | I15: https://doi.org/10.1596/0-8213-4350-5 | K15: 634 | L15: A | M15: A1 | N15: A7 | O15: Africa; African; Australia; Benin; Bolivia; Brazil; Burkina Faso; Chile; China; Europe; European; Ghana; Hungary; India; Indonesia; Kampala; Karnataka; Kolkata; Madhya Pradesh; Mali; Mexico; Odisha; Pakistan; Peru; Philippines; Senegal; Seoul; Southeast Asian; Tanzania; Timor-Leste; Uganda; Ukraine; United States; West Bengal | P15: Multi-region | Q15: Y | T15: review | U15: Y | W15: auto: No AccessStand Alone Books1 Feb 2013Rethinking Decentralization in Developing CountriesAuthors/Editors: Jennie Litvack, Junaid Ahmad, Richard BirdJennie Litvack, Junaid Ahmad, Richard Birdhttps://doi.org/10.1596/0-8213-4350-5SectionsAboutPDF (0.2 MB) ToolsAdd to favoritesDownload CitationsTrack C… | X15: auto: Institutions, interests, ideas and networks in three cases of policy reformHealth Policy and Planning, Vol.31, No.927 May 2016Decentralization of Health and Education in Developing Countries: A Quality-Adjusted Review of the Empirical LiteratureWorld Bank Research Observer, Vol.31, No.220 March 2017Healthcare under the Panchayati Raj Institutions (PRIs) in a decentralised health systemLeadership in Health Services, Vol.29, No.2The path dependence of district manager decision-space in GhanaHea… | Z15: high | AE15: A14:landmarks; A1:landmarks; A7:landmarks | AG15: 12.1991
A16: LM00015 | B16: Does decentralization increase government responsiveness to local needs? | C16: 2003 | D16: Jean-Paul Faguet | E16: Journal of Public Economics | F16: article | G16: 10.1016/s0047-2727(02)00185-8 | H16: W1995980461 | I16: https://doi.org/10.1016/s0047-2727(02)00185-8 | J16: https://www.sciencedirect.com/science/article/pii/S0047272702001858 | K16: 566 | L16: A | M16: A1 | P16: Not place-specific | T16: unclear | U16: Y | Z16: low | AE16: A1:landmarks | AG16: 78.2836
A17: LM00016 | B17: The environment and the entrepreneurial city: searching for the urban ‘sustainability fix’ in Manchester and Leeds | C17: 2004 | D17: Aidan H. While; Andrew E. G. Jonas; David C. Gibbs | E17: International Journal of Urban and Regional Research | F17: article | G17: 10.1111/j.0309-1317.2004.00535.x | H17: W2032751183 | I17: https://doi.org/10.1111/j.0309-1317.2004.00535.x | K17: 562 | L17: A | M17: A1 | O17: Manchester; United Kingdom | P17: Global North | T17: conceptual | U17: Y | W17: auto: In this article we explore how different demands on and for urban environmental policy have played out vis‐à‐vis changing modes and practices of governance in two English post‐industrial cities. | Z17: high | AE17: A1:landmarks | AG17: 29.5553
A18: LM00017 | B18: Du gouvernement des villes à la gouvernance urbaine | C18: 1995 | D18: Patrick Le Galès | E18: Revue française de science politique | F18: article | G18: 10.3406/rfsp.1995.403502 | H18: W2059028256 | I18: https://doi.org/10.3406/rfsp.1995.403502 | K18: 556 | L18: A | M18: A1 | O18: France; United Kingdom; United States | P18: Global North | T18: conceptual | U18: Y | W18: auto: From the governing of cities to urban governance. | Z18: high | AE18: A1:landmarks | AG18: 49.2554
A19: LM00018 | B19: Models of Urban Governance | C19: 1999 | D19: Jon Pierre | E19: Urban Affairs Review | F19: article | G19: 10.1177/10780879922183988 | H19: W2095162523 | I19: https://doi.org/10.1177/10780879922183988 | K19: 515 | L19: A | M19: A1 | O19: Europe | P19: Global North | T19: unclear | U19: Y | W19: auto: Local governments in Western Europe have become increasingly involved in network building with the local business community. | Z19: high | AE19: A1:landmarks | AG19: 33.4298
A20: LM00019 | B20: Inventing Local Democracy | C20: 2000 | D20: Rebecca Neaera Abers | E20: Lynne Rienner Publishers eBooks | F20: book | G20: 10.1515/9781626371378 | H20: W4300242732 | I20: https://doi.org/10.1515/9781626371378 | K20: 513 | L20: A | M20: A1 | O20: Brazil | P20: Latin America | T20: conceptual | U20: Y | W20: auto: Countless studies of citizen participation in public decisionmaking point out the limitations of direct democracy when it is transported from the realm of political theory into the "real world." In contrast, this book examines a case where an innovative city government gave major decisionmaking p… | X20: auto: Countless studies of citizen participation in public decisionmaking point out the limitations of direct democracy when it is transported from the realm of political theory into the "real world." In contrast, this book examines a case where an innovative city government gave major decisionmaking power to ordinary citizens on a large scale—and managed to survive and prosper. | Z20: high | AE20: A1:landmarks | AG20: 11.8416
A21: LM00020 | B21: European Cities | C21: 2002 | D21: Patrick Le Galès | E21: Oxford University Press eBooks | F21: book | G21: 10.1093/acprof:oso/9780199243570.001.0001 | H21: W4254087421 | I21: https://doi.org/10.1093/acprof:oso/9780199243570.001.0001 | K21: 512 | L21: A | M21: A1 | O21: European | P21: Global North | T21: unclear | U21: Y | W21: auto: Taking examples through the European Union, this book explores the impact of the transformation of the nation states on cities and the change of local societies and local governments. | Z21: high | AE21: A1:landmarks | AG21: 18.577
A22: LM00021 | B22: Social Cohesion and Multilevel Urban Governance | C22: 2000 | D22: Ade Kearns; Ray Forrest | E22: Urban Studies | F22: article | G22: 10.1080/00420980050011208 | H22: W2034882398 | I22: https://doi.org/10.1080/00420980050011208 | K22: 499 | L22: A | M22: A1 | P22: Not place-specific | T22: unclear | U22: Y | Z22: low | AE22: A1:landmarks | AG22: 16.5289
A23: LM00022 | B23: Urban governance and the production of new state spaces in western Europe, 1960–2000 | C23: 2004 | D23: Neil Brenner | E23: Review of International Political Economy | F23: article | G23: 10.1080/0969229042000282864 | H23: W4245283280 | I23: https://doi.org/10.1080/0969229042000282864 | K23: 491 | L23: A | M23: A1 | O23: Europe; European | P23: Global North | T23: conceptual | U23: Y | W23: auto: Against the background of contemporary debates on globalization and the crystallization of a post-Westphalian world order, this article develops an interpretation of state spatial restructuring in post-1970s western Europe While many analyses of globalization and the changing state have focused o… | Z23: high | AE23: A1:landmarks | AG23: 41.049
A24: LM00023 | B24: Selling City Futures: The Financialization of Urban Redevelopment Policy | C24: 2010 | D24: Rachel N. Weber | E24: Economic Geography | F24: article | G24: 10.1111/j.1944-8287.2010.01077.x | H24: W1779394378 | I24: https://doi.org/10.1111/j.1944-8287.2010.01077.x | K24: 473 | L24: A | M24: A1 | O24: Chicago; United States | P24: Global North | T24: qualitative | U24: Y | W24: auto: abstract This article examines the specific mechanisms that have allowed global financial markets to penetrate deeply into the activities of U.S. cities. | Z24: high | AE24: A1:landmarks | AG24: 15.2392
A25: LM00024 | B25: Decentralization, Local Government, and the Welfare State | C25: 2007 | D25: Jefferey M. Sellers; Anders Lidström | E25: Governance | F25: article | G25: 10.1111/j.1468-0491.2007.00374.x | H25: W1501190759 | I25: https://doi.org/10.1111/j.1468-0491.2007.00374.x | K25: 463 | L25: A | M25: A1 | P25: Not place-specific | T25: unclear | U25: Y | W25: auto: This article, drawing on the first systematic index of decentralization to local government in 21 countries, demonstrates a close relation between Social Democratic welfare states and an intergovernmental infrastructure that in important respects ranks as the most decentralized among advanced ind… | Z25: medium | AE25: A1:landmarks | AG25: 43.728
A26: LM00025 | B26: Do Political Parties Matter? Evidence from U.S. Cities* | C26: 2009 | D26: Fernando V. Ferreira; Joseph Gyourko | E26: The Quarterly Journal of Economics | F26: article | G26: 10.1162/qjec.2009.124.1.399 | H26: W2135146089 | I26: https://doi.org/10.1162/qjec.2009.124.1.399 | K26: 439 | L26: A | M26: A1 | O26: United States | P26: Global North | T26: quantitative | U26: Y | W26: auto: We investigate three mechanisms that could account for the striking lack of partisan impact at the local level, and find the most support for Tiebout competition among localities within metropolitan areas. | X26: auto: We investigate three mechanisms that could account for the striking lack of partisan impact at the local level, and find the most support for Tiebout competition among localities within metropolitan areas. | Z26: medium | AE26: A1:landmarks | AG26: 141.7297
A27: LM00026 | B27: Source Separation and Decentralization for Wastewater Management | C27: 2013 | D27: Tove A. Larsen; Kai M. Udert; Judit Lienert | E27: IWA Publishing eBooks | F27: book | G27: 10.2166/9781780401072 | H27: W161525005 | I27: https://doi.org/10.2166/9781780401072 | J27: https://doi.org/10.2166/9781780401072 | K27: 433 | L27: A | M27: A1 | P27: Not place-specific | T27: conceptual | U27: Y | W27: auto: The area is in rapid development, but many of the fundamental insights presented in this book will stay valid. | Z27: high | AE27: A1:landmarks | AG27: 36.4917
A28: LM00027 | B28: China's Changing Urban Governance in the Transition Towards a More Market-oriented Economy | C28: 2002 | D28: Fulong Wu | E28: Urban Studies | F28: article | G28: 10.1080/00420980220135491 | H28: W2049842115 | I28: https://doi.org/10.1080/00420980220135491 | K28: 431 | L28: A | M28: A1 | O28: China | P28: China & East Asia | T28: unclear | U28: Y | W28: auto: This article aims to analyse the forces released both inside and outside the formal socialist state system and the impacts on phenomenal restructuring of urban governance, especially at local levels. | X28: auto: Relatively, the governing of Chinese cities is still underresearched. | Z28: high | AE28: A1:landmarks | AG28: 30.1101
A29: LM00028 | B29: China's Local Political Budget Cycles | C29: 2009 | D29: Gang Guo | E29: American Journal of Political Science | F29: article | G29: 10.1111/j.1540-5907.2009.00390.x | H29: W2128534216 | I29: https://doi.org/10.1111/j.1540-5907.2009.00390.x | K29: 429 | L29: A | M29: A1 | O29: China | P29: China & East Asia | T29: quantitative | U29: Y | W29: auto: This article examines the political budget cycles in Chinese counties. | Z29: high | AE29: A1:landmarks | AG29: 25.3844
A30: LM00029 | B30: Decentralisation, participation and accountability in Sahelian forestry: legal instruments of political-administrative control | C30: 1999 | D30: Jesse Ribot | E30: Africa | F30: article | G30: 10.2307/1161076 | H30: W2070217518 | I30: https://doi.org/10.2307/1161076 | K30: 423 | L30: A | M30: A1 | O30: Burkina Faso; Mali | P30: Africa | T30: conceptual | U30: Y | W30: auto: Rather than pitting the state against society by depicting the state as a negative force and society and non-state institutions as positive—as is done in many decentralisation and participatory efforts—this article suggests that representation through local government can be the basis of general … | Z30: high | AE30: A1:landmarks | AG30: 20.1903
A31: LM00030 | B31: Community Development: Creating community alternatives - vision, analysis and practice | C31: 1995 | D31: Jim Ife | E31: UWA Profiles and Research Repository (University of Western Australia) | F31: book | H31: W1525923982 | I31: https://admin.research-repository.uwa.edu.au/en/publications/568f8586-e780-4cca-aef0-c74526cd5e0f | K31: 420 | L31: A | M31: A1 | P31: Not place-specific | T31: conceptual | W31: auto: *The Crisis in Human Services and the Need for Community The crisis in the welfare state Community-based services as an alternative The missing ingredient: community development The next steps *Foundations of Community Work: An Ecological Perspective Environmental crisis Environmental responses a… | Z31: high | AA31: Y | AE31: A1:landmarks | AG31: 5.0739
A32: LM00031 | B32: Resilience, ecology and adaptation in the experimental city | C32: 2011 | D32: James Evans | E32: Transactions of the Institute of British Geographers | F32: article | G32: 10.1111/j.1475-5661.2010.00420.x | H32: W1503263161 | I32: https://doi.org/10.1111/j.1475-5661.2010.00420.x | J32: https://onlinelibrary.wiley.com/doi/pdfdirect/10.1111/j.1475-5661.2010.00420.x | K32: 410 | L32: A | M32: A1 | N32: A7 | O32: United States | P32: Global North | T32: conceptual | U32: Y | W32: auto: This paper traces one particular lineage of experimentation to resilience ecology, which rejects the possibility of external control over a system, casting planning and administrative functions, and even scientists themselves, as part of a Social‐Ecological System. | Z32: high | AE32: A1:landmarks; A7:landmarks | AG32: 18.2627
A33: LM00032 | B33: Financial Intermediation and the Costs of Trading in an Opaque Market | C33: 2006 | D33: Richard C. Green; Burton Hollifield; Norman Schürhoff | E33: Review of Financial Studies | F33: article | G33: 10.1093/rfs/hhl012 | H33: W3022314381 | I33: https://doi.org/10.1093/rfs/hhl012 | K33: 408 | L33: A | M33: A1 | P33: Not place-specific | T33: quantitative | U33: Y | W33: auto: We analyze a database of trades between broker-dealers and customers in municipal bonds. | Z33: high | AE33: A1:landmarks | AG33: 21.3327
A34: LM00033 | B34: Decentralization of health systems in Ghana, Zambia, Uganda and the Philippines: a comparative analysis of decision space | C34: 2002 | D34: Thomas John Bossert | E34: Health Policy and Planning | F34: article | G34: 10.1093/heapol/17.1.14 | H34: W1983617101 | I34: https://doi.org/10.1093/heapol/17.1.14 | J34: https://academic.oup.com/heapol/article-pdf/17/1/14/9806466/170014.pdf | K34: 406 | L34: A | M34: A1 | O34: Ghana; Philippines; Uganda; Zambia | P34: Multi-region | T34: conceptual | U34: Y | W34: auto: This study reviews the experience of decentralization in four developing countries: Ghana, Uganda, Zambia and the Philippines. | X34: auto: The authors suggest that this is a major area for future research. | Z34: medium | AE34: A1:landmarks | AG34: 11.0655
A35: LM00034 | B35: Urban Governance and the Politics of Climate change | C35: 2017 | D35: Vanesa Castán Broto | E35: World Development | F35: article | G35: 10.1016/j.worlddev.2016.12.031 | H35: W2587562756 | I35: https://doi.org/10.1016/j.worlddev.2016.12.031 | J35: https://discovery.ucl.ac.uk/1532905/2/Castan_Broto_Manuscript.pdf | K35: 404 | L35: A | M35: A1 | P35: Not place-specific | T35: unclear | U35: Y | Z35: low | AE35: A1:landmarks | AG35: 25.5082
A36: LM00035 | B36: Telecommunications and Organizational Decentralization | C36: 1975 | D36: Jack M. Nilles | E36: IRE Transactions on Communications Systems | F36: article | G36: 10.1109/tcom.1975.1092687 | H36: W2063371681 | I36: https://doi.org/10.1109/tcom.1975.1092687 | K36: 400 | L36: A | M36: A1 | P36: Not place-specific | T36: conceptual | U36: Y | W36: auto: In recent years, several phenomena have caused significant pressures on the traditional, centralized urban structure. | Z36: high | AE36: A1:landmarks | AG36: 0
A37: LM00036 | B37: Social Innovation and Civil Society in Urban Governance: Strategies for an Inclusive City | C37: 2005 | D37: Julia Gerometta; Hartmut Häußermann; Giulia Longo | E37: Urban Studies | F37: article | G37: 10.1080/00420980500279851 | H37: W2116855395 | I37: https://doi.org/10.1080/00420980500279851 | K37: 398 | L37: A | M37: A1 | P37: Not place-specific | T37: unclear | U37: Y | W37: auto: This article seeks to explore the role of civil society in new urban governance arrangements that will hopefully contribute to counter the trends towards social exclusion. | Z37: high | AE37: A1:landmarks | AG37: 20.6616
A38: LM00037 | B38: Adaptive urban governance: new challenges for the second generation of urban adaptation strategies to climate change | C38: 2010 | D38: Joern Birkmann; Matthias Garschagen; Frauke Kraas; Nguyen Quang | E38: Sustainability Science | F38: article | G38: 10.1007/s11625-010-0111-3 | H38: W1996012883 | I38: https://doi.org/10.1007/s11625-010-0111-3 | K38: 396 | L38: A | M38: A1 | P38: Not place-specific | T38: unclear | U38: Y | Z38: low | AE38: A1:landmarks | AG38: 13.9246
A39: LM00038 | B39: The reform of intergovernmental fiscal relations in developing and emerging market economies | C39: 1994 | D39: Anwar Ali Shah | E39: World Bank, Washington, DC eBooks | F39: book | G39: 10.1596/0-8213-2836-0 | H39: W1526821310 | I39: https://doi.org/10.1596/0-8213-2836-0 | K39: 389 | L39: A | M39: A1 | O39: Africa; Argentina; Benin; Bolivia; Brazil; China; European; Indonesia; Ireland; Latin AmericaLatin; Latin AmericaSSRN; Latin American; Mali; Mexico; Pakistan; Philippines; Poland; South Korea; Switzerland; Vietnam | P39: Multi-region | T39: review | U39: Y | W39: auto: No AccessStand Alone Books1 Feb 2013The reform of intergovernmental fiscal relations in developing and emerging market economiesAuthors/Editors: Anwar ShahAnwar Shahhttps://doi.org/10.1596/0-8213-2836-0SectionsAboutPDF (0.6 MB) ToolsAdd to favoritesDownload CitationsTrack Citations ShareFacebookT… | X39: auto: Comparative PerspectivePublic Administration Review, Vol.69Fiscal Decentralization, Chinese Style: Good for Health Outcomes?World Development, Vol.37, No.12Assigning State Taxes in a Federal Country: The Case of AustraliaSSRN Electronic JournalResource Windfalls, Fiscal Effort and Public Spending: Evidence from Brazilian MunicipalitiesSSRN Electronic JournalFiscal Federalism in the European Union: How Far Are We?Citizen-centred Local Governance: Strategies to combat democratic deficitsDevelop… | Z39: high | AE39: A1:landmarks | AG39: 17.1557
A40: LM00039 | B40: Decentralisation in Africa: goals, dimensions, myths and challenges | C40: 2003 | D40: Paul Smoke | E40: Public Administration and Development | F40: article | G40: 10.1002/pad.255 | H40: W1974289285 | I40: https://doi.org/10.1002/pad.255 | K40: 384 | L40: A | M40: A1 | O40: Africa | P40: Africa | T40: unclear | U40: Y | W40: auto: Drawing selectively on the large academic and practitioner literature on decentralisation and the articles in this volume, this article briefly outlines a number of typical prominent goals of decentralisation. | Z40: medium | AE40: A1:landmarks | AG40: 56.535
...

Sheet Gap matrix
A1: Gap matrix — live COUNTIFS over the Records tab (counts update when rows are added)
A2: Counts are of records in this bibliography (a sample), not of all literature; use the Growth tab for OpenAlex-wide counts. Records found only by the supplementary query set (Supplementary = Y) are excluded.
A4: Theme × region
A5: Theme | B5: Name | C5: Global North | D5: China & East Asia | E5: South Asia | F5: Southeast Asia | G5: Africa | H5: Latin America | I5: Middle East | J5: Multi-region | K5: Not place-specific | L5: Total | M5: India flag
A6: A1 | B6: Urban governance, decentralisation & municipal finance | C6: =COUNTIFS(Records!$M:$M,$A6,Records!$AB:$AB,"<>Y",Records!$P:$P,C$5) | D6: =COUNTIFS(Records!$M:$M,$A6,Records!$AB:$AB,"<>Y",Records!$P:$P,D$5) | E6: =COUNTIFS(Records!$M:$M,$A6,Records!$AB:$AB,"<>Y",Records!$P:$P,E$5) | F6: =COUNTIFS(Records!$M:$M,$A6,Records!$AB:$AB,"<>Y",Records!$P:$P,F$5) | G6: =COUNTIFS(Records!$M:$M,$A6,Records!$AB:$AB,"<>Y",Records!$P:$P,G$5) | H6: =COUNTIFS(Records!$M:$M,$A6,Records!$AB:$AB,"<>Y",Records!$P:$P,H$5) | I6: =COUNTIFS(Records!$M:$M,$A6,Records!$AB:$AB,"<>Y",Records!$P:$P,I$5) | J6: =COUNTIFS(Records!$M:$M,$A6,Records!$AB:$AB,"<>Y",Records!$P:$P,J$5) | K6: =COUNTIFS(Records!$M:$M,$A6,Records!$AB:$AB,"<>Y",Records!$P:$P,K$5) | L6: =COUNTIFS(Records!$M:$M,$A6,Records!$AB:$AB,"<>Y") | M6: =COUNTIFS(Records!$M:$M,$A6,Records!$AB:$AB,"<>Y",Records!$Q:$Q,"Y")
A7: A2 | B7: Planning, master plans & land-use regulation | C7: =COUNTIFS(Records!$M:$M,$A7,Records!$AB:$AB,"<>Y",Records!$P:$P,C$5) | D7: =COUNTIFS(Records!$M:$M,$A7,Records!$AB:$AB,"<>Y",Records!$P:$P,D$5) | E7: =COUNTIFS(Records!$M:$M,$A7,Records!$AB:$AB,"<>Y",Records!$P:$P,E$5) | F7: =COUNTIFS(Records!$M:$M,$A7,Records!$AB:$AB,"<>Y",Records!$P:$P,F$5) | G7: =COUNTIFS(Records!$M:$M,$A7,Records!$AB:$AB,"<>Y",Records!$P:$P,G$5) | H7: =COUNTIFS(Records!$M:$M,$A7,Records!$AB:$AB,"<>Y",Records!$P:$P,H$5) | I7: =COUNTIFS(Records!$M:$M,$A7,Records!$AB:$AB,"<>Y",Records!$P:$P,I$5) | J7: =COUNTIFS(Records!$M:$M,$A7,Records!$AB:$AB,"<>Y",Records!$P:$P,J$5) | K7: =COUNTIFS(Records!$M:$M,$A7,Records!$AB:$AB,"<>Y",Records!$P:$P,K$5) | L7: =COUNTIFS(Records!$M:$M,$A7,Records!$AB:$AB,"<>Y") | M7: =COUNTIFS(Records!$M:$M,$A7,Records!$AB:$AB,"<>Y",Records!$Q:$Q,"Y")
A8: A3 | B8: Housing, informality & slums | C8: =COUNTIFS(Records!$M:$M,$A8,Records!$AB:$AB,"<>Y",Records!$P:$P,C$5) | D8: =COUNTIFS(Records!$M:$M,$A8,Records!$AB:$AB,"<>Y",Records!$P:$P,D$5) | E8: =COUNTIFS(Records!$M:$M,$A8,Records!$AB:$AB,"<>Y",Records!$P:$P,E$5) | F8: =COUNTIFS(Records!$M:$M,$A8,Records!$AB:$AB,"<>Y",Records!$P:$P,F$5) | G8: =COUNTIFS(Records!$M:$M,$A8,Records!$AB:$AB,"<>Y",Records!$P:$P,G$5) | H8: =COUNTIFS(Records!$M:$M,$A8,Records!$AB:$AB,"<>Y",Records!$P:$P,H$5) | I8: =COUNTIFS(Records!$M:$M,$A8,Records!$AB:$AB,"<>Y",Records!$P:$P,I$5) | J8: =COUNTIFS(Records!$M:$M,$A8,Records!$AB:$AB,"<>Y",Records!$P:$P,J$5) | K8: =COUNTIFS(Records!$M:$M,$A8,Records!$AB:$AB,"<>Y",Records!$P:$P,K$5) | L8: =COUNTIFS(Records!$M:$M,$A8,Records!$AB:$AB,"<>Y") | M8: =COUNTIFS(Records!$M:$M,$A8,Records!$AB:$AB,"<>Y",Records!$Q:$Q,"Y")
A9: A4 | B9: Eviction, resettlement & displacement | C9: =COUNTIFS(Records!$M:$M,$A9,Records!$AB:$AB,"<>Y",Records!$P:$P,C$5) | D9: =COUNTIFS(Records!$M:$M,$A9,Records!$AB:$AB,"<>Y",Records!$P:$P,D$5) | E9: =COUNTIFS(Records!$M:$M,$A9,Records!$AB:$AB,"<>Y",Records!$P:$P,E$5) | F9: =COUNTIFS(Records!$M:$M,$A9,Records!$AB:$AB,"<>Y",Records!$P:$P,F$5) | G9: =COUNTIFS(Records!$M:$M,$A9,Records!$AB:$AB,"<>Y",Records!$P:$P,G$5) | H9: =COUNTIFS(Records!$M:$M,$A9,Records!$AB:$AB,"<>Y",Records!$P:$P,H$5) | I9: =COUNTIFS(Records!$M:$M,$A9,Records!$AB:$AB,"<>Y",Records!$P:$P,I$5) | J9: =COUNTIFS(Records!$M:$M,$A9,Records!$AB:$AB,"<>Y",Records!$P:$P,J$5) | K9: =COUNTIFS(Records!$M:$M,$A9,Records!$AB:$AB,"<>Y",Records!$P:$P,K$5) | L9: =COUNTIFS(Records!$M:$M,$A9,Records!$AB:$AB,"<>Y") | M9: =COUNTIFS(Records!$M:$M,$A9,Records!$AB:$AB,"<>Y",Records!$Q:$Q,"Y")
A10: A5 | B10: Land, peri-urban & extended urbanisation | C10: =COUNTIFS(Records!$M:$M,$A10,Records!$AB:$AB,"<>Y",Records!$P:$P,C$5) | D10: =COUNTIFS(Records!$M:$M,$A10,Records!$AB:$AB,"<>Y",Records!$P:$P,D$5) | E10: =COUNTIFS(Records!$M:$M,$A10,Records!$AB:$AB,"<>Y",Records!$P:$P,E$5) | F10: =COUNTIFS(Records!$M:$M,$A10,Records!$AB:$AB,"<>Y",Records!$P:$P,F$5) | G10: =COUNTIFS(Records!$M:$M,$A10,Records!$AB:$AB,"<>Y",Records!$P:$P,G$5) | H10: =COUNTIFS(Records!$M:$M,$A10,Records!$AB:$AB,"<>Y",Records!$P:$P,H$5) | I10: =COUNTIFS(Records!$M:$M,$A10,Records!$AB:$AB,"<>Y",Records!$P:$P,I$5) | J10: =COUNTIFS(Records!$M:$M,$A10,Records!$AB:$AB,"<>Y",Records!$P:$P,J$5) | K10: =COUNTIFS(Records!$M:$M,$A10,Records!$AB:$AB,"<>Y",Records!$P:$P,K$5) | L10: =COUNTIFS(Records!$M:$M,$A10,Records!$AB:$AB,"<>Y") | M10: =COUNTIFS(Records!$M:$M,$A10,Records!$AB:$AB,"<>Y",Records!$Q:$Q,"Y")
A11: A6 | B11: Small towns, census towns & secondary cities | C11: =COUNTIFS(Records!$M:$M,$A11,Records!$AB:$AB,"<>Y",Records!$P:$P,C$5) | D11: =COUNTIFS(Records!$M:$M,$A11,Records!$AB:$AB,"<>Y",Records!$P:$P,D$5) | E11: =COUNTIFS(Records!$M:$M,$A11,Records!$AB:$AB,"<>Y",Records!$P:$P,E$5) | F11: =COUNTIFS(Records!$M:$M,$A11,Records!$AB:$AB,"<>Y",Records!$P:$P,F$5) | G11: =COUNTIFS(Records!$M:$M,$A11,Records!$AB:$AB,"<>Y",Records!$P:$P,G$5) | H11: =COUNTIFS(Records!$M:$M,$A11,Records!$AB:$AB,"<>Y",Records!$P:$P,H$5) | I11: =COUNTIFS(Records!$M:$M,$A11,Records!$AB:$AB,"<>Y",Records!$P:$P,I$5) | J11: =COUNTIFS(Records!$M:$M,$A11,Records!$AB:$AB,"<>Y",Records!$P:$P,J$5) | K11: =COUNTIFS(Records!$M:$M,$A11,Records!$AB:$AB,"<>Y",Records!$P:$P,K$5) | L11: =COUNTIFS(Records!$M:$M,$A11,Records!$AB:$AB,"<>Y") | M11: =COUNTIFS(Records!$M:$M,$A11,Records!$AB:$AB,"<>Y",Records!$Q:$Q,"Y")
A12: A7 | B12: Urban infrastructure (water, sanitation, energy) & infrastructural citizenship | C12: =COUNTIFS(Records!$M:$M,$A12,Records!$AB:$AB,"<>Y",Records!$P:$P,C$5) | D12: =COUNTIFS(Records!$M:$M,$A12,Records!$AB:$AB,"<>Y",Records!$P:$P,D$5) | E12: =COUNTIFS(Records!$M:$M,$A12,Records!$AB:$AB,"<>Y",Records!$P:$P,E$5) | F12: =COUNTIFS(Records!$M:$M,$A12,Records!$AB:$AB,"<>Y",Records!$P:$P,F$5) | G12: =COUNTIFS(Records!$M:$M,$A12,Records!$AB:$AB,"<>Y",Records!$P:$P,G$5) | H12: =COUNTIFS(Records!$M:$M,$A12,Records!$AB:$AB,"<>Y",Records!$P:$P,H$5) | I12: =COUNTIFS(Records!$M:$M,$A12,Records!$AB:$AB,"<>Y",Records!$P:$P,I$5) | J12: =COUNTIFS(Records!$M:$M,$A12,Records!$AB:$AB,"<>Y",Records!$P:$P,J$5) | K12: =COUNTIFS(Records!$M:$M,$A12,Records!$AB:$AB,"<>Y",Records!$P:$P,K$5) | L12: =COUNTIFS(Records!$M:$M,$A12,Records!$AB:$AB,"<>Y") | M12: =COUNTIFS(Records!$M:$M,$A12,Records!$AB:$AB,"<>Y",Records!$Q:$Q,"Y")
A13: A8 | B13: Mobility & transport (social science) | C13: =COUNTIFS(Records!$M:$M,$A13,Records!$AB:$AB,"<>Y",Records!$P:$P,C$5) | D13: =COUNTIFS(Records!$M:$M,$A13,Records!$AB:$AB,"<>Y",Records!$P:$P,D$5) | E13: =COUNTIFS(Records!$M:$M,$A13,Records!$AB:$AB,"<>Y",Records!$P:$P,E$5) | F13: =COUNTIFS(Records!$M:$M,$A13,Records!$AB:$AB,"<>Y",Records!$P:$P,F$5) | G13: =COUNTIFS(Records!$M:$M,$A13,Records!$AB:$AB,"<>Y",Records!$P:$P,G$5) | H13: =COUNTIFS(Records!$M:$M,$A13,Records!$AB:$AB,"<>Y",Records!$P:$P,H$5) | I13: =COUNTIFS(Records!$M:$M,$A13,Records!$AB:$AB,"<>Y",Records!$P:$P,I$5) | J13: =COUNTIFS(Records!$M:$M,$A13,Records!$AB:$AB,"<>Y",Records!$P:$P,J$5) | K13: =COUNTIFS(Records!$M:$M,$A13,Records!$AB:$AB,"<>Y",Records!$P:$P,K$5) | L13: =COUNTIFS(Records!$M:$M,$A13,Records!$AB:$AB,"<>Y") | M13: =COUNTIFS(Records!$M:$M,$A13,Records!$AB:$AB,"<>Y",Records!$Q:$Q,"Y")
A14: A9 | B14: Public space, publicness & the street | C14: =COUNTIFS(Records!$M:$M,$A14,Records!$AB:$AB,"<>Y",Records!$P:$P,C$5) | D14: =COUNTIFS(Records!$M:$M,$A14,Records!$AB:$AB,"<>Y",Records!$P:$P,D$5) | E14: =COUNTIFS(Records!$M:$M,$A14,Records!$AB:$AB,"<>Y",Records!$P:$P,E$5) | F14: =COUNTIFS(Records!$M:$M,$A14,Records!$AB:$AB,"<>Y",Records!$P:$P,F$5) | G14: =COUNTIFS(Records!$M:$M,$A14,Records!$AB:$AB,"<>Y",Records!$P:$P,G$5) | H14: =COUNTIFS(Records!$M:$M,$A14,Records!$AB:$AB,"<>Y",Records!$P:$P,H$5) | I14: =COUNTIFS(Records!$M:$M,$A14,Records!$AB:$AB,"<>Y",Records!$P:$P,I$5) | J14: =COUNTIFS(Records!$M:$M,$A14,Records!$AB:$AB,"<>Y",Records!$P:$P,J$5) | K14: =COUNTIFS(Records!$M:$M,$A14,Records!$AB:$AB,"<>Y",Records!$P:$P,K$5) | L14: =COUNTIFS(Records!$M:$M,$A14,Records!$AB:$AB,"<>Y") | M14: =COUNTIFS(Records!$M:$M,$A14,Records!$AB:$AB,"<>Y",Records!$Q:$Q,"Y")
A15: A10 | B15: Urban economy, informal work & street vending | C15: =COUNTIFS(Records!$M:$M,$A15,Records!$AB:$AB,"<>Y",Records!$P:$P,C$5) | D15: =COUNTIFS(Records!$M:$M,$A15,Records!$AB:$AB,"<>Y",Records!$P:$P,D$5) | E15: =COUNTIFS(Records!$M:$M,$A15,Records!$AB:$AB,"<>Y",Records!$P:$P,E$5) | F15: =COUNTIFS(Records!$M:$M,$A15,Records!$AB:$AB,"<>Y",Records!$P:$P,F$5) | G15: =COUNTIFS(Records!$M:$M,$A15,Records!$AB:$AB,"<>Y",Records!$P:$P,G$5) | H15: =COUNTIFS(Records!$M:$M,$A15,Records!$AB:$AB,"<>Y",Records!$P:$P,H$5) | I15: =COUNTIFS(Records!$M:$M,$A15,Records!$AB:$AB,"<>Y",Records!$P:$P,I$5) | J15: =COUNTIFS(Records!$M:$M,$A15,Records!$AB:$AB,"<>Y",Records!$P:$P,J$5) | K15: =COUNTIFS(Records!$M:$M,$A15,Records!$AB:$AB,"<>Y",Records!$P:$P,K$5) | L15: =COUNTIFS(Records!$M:$M,$A15,Records!$AB:$AB,"<>Y") | M15: =COUNTIFS(Records!$M:$M,$A15,Records!$AB:$AB,"<>Y",Records!$Q:$Q,"Y")
A16: A11 | B16: Migration & the city | C16: =COUNTIFS(Records!$M:$M,$A16,Records!$AB:$AB,"<>Y",Records!$P:$P,C$5) | D16: =COUNTIFS(Records!$M:$M,$A16,Records!$AB:$AB,"<>Y",Records!$P:$P,D$5) | E16: =COUNTIFS(Records!$M:$M,$A16,Records!$AB:$AB,"<>Y",Records!$P:$P,E$5) | F16: =COUNTIFS(Records!$M:$M,$A16,Records!$AB:$AB,"<>Y",Records!$P:$P,F$5) | G16: =COUNTIFS(Records!$M:$M,$A16,Records!$AB:$AB,"<>Y",Records!$P:$P,G$5) | H16: =COUNTIFS(Records!$M:$M,$A16,Records!$AB:$AB,"<>Y",Records!$P:$P,H$5) | I16: =COUNTIFS(Records!$M:$M,$A16,Records!$AB:$AB,"<>Y",Records!$P:$P,I$5) | J16: =COUNTIFS(Records!$M:$M,$A16,Records!$AB:$AB,"<>Y",Records!$P:$P,J$5) | K16: =COUNTIFS(Records!$M:$M,$A16,Records!$AB:$AB,"<>Y",Records!$P:$P,K$5) | L16: =COUNTIFS(Records!$M:$M,$A16,Records!$AB:$AB,"<>Y") | M16: =COUNTIFS(Records!$M:$M,$A16,Records!$AB:$AB,"<>Y",Records!$Q:$Q,"Y")
A17: A12 | B17: Gender, caste, class & the city | C17: =COUNTIFS(Records!$M:$M,$A17,Records!$AB:$AB,"<>Y",Records!$P:$P,C$5) | D17: =COUNTIFS(Records!$M:$M,$A17,Records!$AB:$AB,"<>Y",Records!$P:$P,D$5) | E17: =COUNTIFS(Records!$M:$M,$A17,Records!$AB:$AB,"<>Y",Records!$P:$P,E$5) | F17: =COUNTIFS(Records!$M:$M,$A17,Records!$AB:$AB,"<>Y",Records!$P:$P,F$5) | G17: =COUNTIFS(Records!$M:$M,$A17,Records!$AB:$AB,"<>Y",Records!$P:$P,G$5) | H17: =COUNTIFS(Records!$M:$M,$A17,Records!$AB:$AB,"<>Y",Records!$P:$P,H$5) | I17: =COUNTIFS(Records!$M:$M,$A17,Records!$AB:$AB,"<>Y",Records!$P:$P,I$5) | J17: =COUNTIFS(Records!$M:$M,$A17,Records!$AB:$AB,"<>Y",Records!$P:$P,J$5) | K17: =COUNTIFS(Records!$M:$M,$A17,Records!$AB:$AB,"<>Y",Records!$P:$P,K$5) | L17: =COUNTIFS(Records!$M:$M,$A17,Records!$AB:$AB,"<>Y") | M17: =COUNTIFS(Records!$M:$M,$A17,Records!$AB:$AB,"<>Y",Records!$Q:$Q,"Y")
... A53: C18 | B53: Neighbourhood platforms & digital public space (WhatsApp, Nextdoor, RWA groups) | C53: =COUNTIFS(Records!$M:$M,$A53,Records!$AB:$AB,"<>Y",Records!$P:$P,C$5) | D53: =COUNTIFS(Records!$M:$M,$A53,Records!$AB:$AB,"<>Y",Records!$P:$P,D$5) | E53: =COUNTIFS(Records!$M:$M,$A53,Records!$AB:$AB,"<>Y",Records!$P:$P,E$5) | F53: =COUNTIFS(Records!$M:$M,$A53,Records!$AB:$AB,"<>Y",Records!$P:$P,F$5) | G53: =COUNTIFS(Records!$M:$M,$A53,Records!$AB:$AB,"<>Y",Records!$P:$P,G$5) | H53: =COUNTIFS(Records!$M:$M,$A53,Records!$AB:$AB,"<>Y",Records!$P:$P,H$5) | I53: =COUNTIFS(Records!$M:$M,$A53,Records!$AB:$AB,"<>Y",Records!$P:$P,I$5) | J53: =COUNTIFS(Records!$M:$M,$A53,Records!$AB:$AB,"<>Y",Records!$P:$P,J$5) | K53: =COUNTIFS(Records!$M:$M,$A53,Records!$AB:$AB,"<>Y",Records!$P:$P,K$5) | L53: =COUNTIFS(Records!$M:$M,$A53,Records!$AB:$AB,"<>Y") | M53: =COUNTIFS(Records!$M:$M,$A53,Records!$AB:$AB,"<>Y",Records!$Q:$Q,"Y")
B54: All themes | C54: =SUM(C6:C53) | D54: =SUM(D6:D53) | E54: =SUM(E6:E53) | F54: =SUM(F6:F53) | G54: =SUM(G6:G53) | H54: =SUM(H6:H53) | I54: =SUM(I6:I53) | J54: =SUM(J6:J53) | ... M54: =SUM(M6:M53)
A57: Theme × method (inferred from abstract)
A58: Theme | B58: Name | C58: qualitative | D58: quantitative | E58: mixed | F58: review | G58: conceptual | H58: computational | I58: unclear | J58: Total | K58: India flag
A59: A1 | B59: Urban governance, decentralisation & municipal finance | C59: =COUNTIFS(Records!$M:$M,$A59,Records!$AB:$AB,"<>Y",Records!$T:$T,C$58) | D59: =COUNTIFS(Records!$M:$M,$A59,Records!$AB:$AB,"<>Y",Records!$T:$T,D$58) | E59: =COUNTIFS(Records!$M:$M,$A59,Records!$AB:$AB,"<>Y",Records!$T:$T,E$58) | F59: =COUNTIFS(Records!$M:$M,$A59,Records!$AB:$AB,"<>Y",Records!$T:$T,F$58) | G59: =COUNTIFS(Records!$M:$M,$A59,Records!$AB:$AB,"<>Y",Records!$T:$T,G$58) | H59: =COUNTIFS(Records!$M:$M,$A59,Records!$AB:$AB,"<>Y",Records!$T:$T,H$58) | I59: =COUNTIFS(Records!$M:$M,$A59,Records!$AB:$AB,"<>Y",Records!$T:$T,I$58) | J59: =COUNTIFS(Records!$M:$M,$A59,Records!$AB:$AB,"<>Y") | K59: =COUNTIFS(Records!$M:$M,$A59,Records!$AB:$AB,"<>Y",Records!$Q:$Q,"Y")
A60: A2 | B60: Planning, master plans & land-use regulation | C60: =COUNTIFS(Records!$M:$M,$A60,Records!$AB:$AB,"<>Y",Records!$T:$T,C$58) | D60: =COUNTIFS(Records!$M:$M,$A60,Records!$AB:$AB,"<>Y",Records!$T:$T,D$58) | E60: =COUNTIFS(Records!$M:$M,$A60,Records!$AB:$AB,"<>Y",Records!$T:$T,E$58) | F60: =COUNTIFS(Records!$M:$M,$A60,Records!$AB:$AB,"<>Y",Records!$T:$T,F$58) | G60: =COUNTIFS(Records!$M:$M,$A60,Records!$AB:$AB,"<>Y",Records!$T:$T,G$58) | H60: =COUNTIFS(Records!$M:$M,$A60,Records!$AB:$AB,"<>Y",Records!$T:$T,H$58) | I60: =COUNTIFS(Records!$M:$M,$A60,Records!$AB:$AB,"<>Y",Records!$T:$T,I$58) | J60: =COUNTIFS(Records!$M:$M,$A60,Records!$AB:$AB,"<>Y") | K60: =COUNTIFS(Records!$M:$M,$A60,Records!$AB:$AB,"<>Y",Records!$Q:$Q,"Y")
A61: A3 | B61: Housing, informality & slums | C61: =COUNTIFS(Records!$M:$M,$A61,Records!$AB:$AB,"<>Y",Records!$T:$T,C$58) | D61: =COUNTIFS(Records!$M:$M,$A61,Records!$AB:$AB,"<>Y",Records!$T:$T,D$58) | E61: =COUNTIFS(Records!$M:$M,$A61,Records!$AB:$AB,"<>Y",Records!$T:$T,E$58) | F61: =COUNTIFS(Records!$M:$M,$A61,Records!$AB:$AB,"<>Y",Records!$T:$T,F$58) | G61: =COUNTIFS(Records!$M:$M,$A61,Records!$AB:$AB,"<>Y",Records!$T:$T,G$58) | H61: =COUNTIFS(Records!$M:$M,$A61,Records!$AB:$AB,"<>Y",Records!$T:$T,H$58) | I61: =COUNTIFS(Records!$M:$M,$A61,Records!$AB:$AB,"<>Y",Records!$T:$T,I$58) | J61: =COUNTIFS(Records!$M:$M,$A61,Records!$AB:$AB,"<>Y") | K61: =COUNTIFS(Records!$M:$M,$A61,Records!$AB:$AB,"<>Y",Records!$Q:$Q,"Y")
A62: A4 | B62: Eviction, resettlement & displacement | C62: =COUNTIFS(Records!$M:$M,$A62,Records!$AB:$AB,"<>Y",Records!$T:$T,C$58) | D62: =COUNTIFS(Records!$M:$M,$A62,Records!$AB:$AB,"<>Y",Records!$T:$T,D$58) | E62: =COUNTIFS(Records!$M:$M,$A62,Records!$AB:$AB,"<>Y",Records!$T:$T,E$58) | F62: =COUNTIFS(Records!$M:$M,$A62,Records!$AB:$AB,"<>Y",Records!$T:$T,F$58) | G62: =COUNTIFS(Records!$M:$M,$A62,Records!$AB:$AB,"<>Y",Records!$T:$T,G$58) | H62: =COUNTIFS(Records!$M:$M,$A62,Records!$AB:$AB,"<>Y",Records!$T:$T,H$58) | I62: =COUNTIFS(Records!$M:$M,$A62,Records!$AB:$AB,"<>Y",Records!$T:$T,I$58) | J62: =COUNTIFS(Records!$M:$M,$A62,Records!$AB:$AB,"<>Y") | K62: =COUNTIFS(Records!$M:$M,$A62,Records!$AB:$AB,"<>Y",Records!$Q:$Q,"Y")
A63: A5 | B63: Land, peri-urban & extended urbanisation | C63: =COUNTIFS(Records!$M:$M,$A63,Records!$AB:$AB,"<>Y",Records!$T:$T,C$58) | D63: =COUNTIFS(Records!$M:$M,$A63,Records!$AB:$AB,"<>Y",Records!$T:$T,D$58) | E63: =COUNTIFS(Records!$M:$M,$A63,Records!$AB:$AB,"<>Y",Records!$T:$T,E$58) | F63: =COUNTIFS(Records!$M:$M,$A63,Records!$AB:$AB,"<>Y",Records!$T:$T,F$58) | G63: =COUNTIFS(Records!$M:$M,$A63,Records!$AB:$AB,"<>Y",Records!$T:$T,G$58) | H63: =COUNTIFS(Records!$M:$M,$A63,Records!$AB:$AB,"<>Y",Records!$T:$T,H$58) | I63: =COUNTIFS(Records!$M:$M,$A63,Records!$AB:$AB,"<>Y",Records!$T:$T,I$58) | J63: =COUNTIFS(Records!$M:$M,$A63,Records!$AB:$AB,"<>Y") | K63: =COUNTIFS(Records!$M:$M,$A63,Records!$AB:$AB,"<>Y",Records!$Q:$Q,"Y")
A64: A6 | B64: Small towns, census towns & secondary cities | C64: =COUNTIFS(Records!$M:$M,$A64,Records!$AB:$AB,"<>Y",Records!$T:$T,C$58) | D64: =COUNTIFS(Records!$M:$M,$A64,Records!$AB:$AB,"<>Y",Records!$T:$T,D$58) | E64: =COUNTIFS(Records!$M:$M,$A64,Records!$AB:$AB,"<>Y",Records!$T:$T,E$58) | F64: =COUNTIFS(Records!$M:$M,$A64,Records!$AB:$AB,"<>Y",Records!$T:$T,F$58) | G64: =COUNTIFS(Records!$M:$M,$A64,Records!$AB:$AB,"<>Y",Records!$T:$T,G$58) | H64: =COUNTIFS(Records!$M:$M,$A64,Records!$AB:$AB,"<>Y",Records!$T:$T,H$58) | I64: =COUNTIFS(Records!$M:$M,$A64,Records!$AB:$AB,"<>Y",Records!$T:$T,I$58) | J64: =COUNTIFS(Records!$M:$M,$A64,Records!$AB:$AB,"<>Y") | K64: =COUNTIFS(Records!$M:$M,$A64,Records!$AB:$AB,"<>Y",Records!$Q:$Q,"Y")
A65: A7 | B65: Urban infrastructure (water, sanitation, energy) & infrastructural citizenship | C65: =COUNTIFS(Records!$M:$M,$A65,Records!$AB:$AB,"<>Y",Records!$T:$T,C$58) | D65: =COUNTIFS(Records!$M:$M,$A65,Records!$AB:$AB,"<>Y",Records!$T:$T,D$58) | E65: =COUNTIFS(Records!$M:$M,$A65,Records!$AB:$AB,"<>Y",Records!$T:$T,E$58) | F65: =COUNTIFS(Records!$M:$M,$A65,Records!$AB:$AB,"<>Y",Records!$T:$T,F$58) | G65: =COUNTIFS(Records!$M:$M,$A65,Records!$AB:$AB,"<>Y",Records!$T:$T,G$58) | H65: =COUNTIFS(Records!$M:$M,$A65,Records!$AB:$AB,"<>Y",Records!$T:$T,H$58) | I65: =COUNTIFS(Records!$M:$M,$A65,Records!$AB:$AB,"<>Y",Records!$T:$T,I$58) | J65: =COUNTIFS(Records!$M:$M,$A65,Records!$AB:$AB,"<>Y") | K65: =COUNTIFS(Records!$M:$M,$A65,Records!$AB:$AB,"<>Y",Records!$Q:$Q,"Y")
A66: A8 | B66: Mobility & transport (social science) | C66: =COUNTIFS(Records!$M:$M,$A66,Records!$AB:$AB,"<>Y",Records!$T:$T,C$58) | D66: =COUNTIFS(Records!$M:$M,$A66,Records!$AB:$AB,"<>Y",Records!$T:$T,D$58) | E66: =COUNTIFS(Records!$M:$M,$A66,Records!$AB:$AB,"<>Y",Records!$T:$T,E$58) | F66: =COUNTIFS(Records!$M:$M,$A66,Records!$AB:$AB,"<>Y",Records!$T:$T,F$58) | G66: =COUNTIFS(Records!$M:$M,$A66,Records!$AB:$AB,"<>Y",Records!$T:$T,G$58) | H66: =COUNTIFS(Records!$M:$M,$A66,Records!$AB:$AB,"<>Y",Records!$T:$T,H$58) | I66: =COUNTIFS(Records!$M:$M,$A66,Records!$AB:$AB,"<>Y",Records!$T:$T,I$58) | J66: =COUNTIFS(Records!$M:$M,$A66,Records!$AB:$AB,"<>Y") | K66: =COUNTIFS(Records!$M:$M,$A66,Records!$AB:$AB,"<>Y",Records!$Q:$Q,"Y")
A67: A9 | B67: Public space, publicness & the street | C67: =COUNTIFS(Records!$M:$M,$A67,Records!$AB:$AB,"<>Y",Records!$T:$T,C$58) | D67: =COUNTIFS(Records!$M:$M,$A67,Records!$AB:$AB,"<>Y",Records!$T:$T,D$58) | E67: =COUNTIFS(Records!$M:$M,$A67,Records!$AB:$AB,"<>Y",Records!$T:$T,E$58) | F67: =COUNTIFS(Records!$M:$M,$A67,Records!$AB:$AB,"<>Y",Records!$T:$T,F$58) | G67: =COUNTIFS(Records!$M:$M,$A67,Records!$AB:$AB,"<>Y",Records!$T:$T,G$58) | H67: =COUNTIFS(Records!$M:$M,$A67,Records!$AB:$AB,"<>Y",Records!$T:$T,H$58) | I67: =COUNTIFS(Records!$M:$M,$A67,Records!$AB:$AB,"<>Y",Records!$T:$T,I$58) | J67: =COUNTIFS(Records!$M:$M,$A67,Records!$AB:$AB,"<>Y") | K67: =COUNTIFS(Records!$M:$M,$A67,Records!$AB:$AB,"<>Y",Records!$Q:$Q,"Y")
A68: A10 | B68: Urban economy, informal work & street vending | C68: =COUNTIFS(Records!$M:$M,$A68,Records!$AB:$AB,"<>Y",Records!$T:$T,C$58) | D68: =COUNTIFS(Records!$M:$M,$A68,Records!$AB:$AB,"<>Y",Records!$T:$T,D$58) | E68: =COUNTIFS(Records!$M:$M,$A68,Records!$AB:$AB,"<>Y",Records!$T:$T,E$58) | F68: =COUNTIFS(Records!$M:$M,$A68,Records!$AB:$AB,"<>Y",Records!$T:$T,F$58) | G68: =COUNTIFS(Records!$M:$M,$A68,Records!$AB:$AB,"<>Y",Records!$T:$T,G$58) | H68: =COUNTIFS(Records!$M:$M,$A68,Records!$AB:$AB,"<>Y",Records!$T:$T,H$58) | I68: =COUNTIFS(Records!$M:$M,$A68,Records!$AB:$AB,"<>Y",Records!$T:$T,I$58) | J68: =COUNTIFS(Records!$M:$M,$A68,Records!$AB:$AB,"<>Y") | K68: =COUNTIFS(Records!$M:$M,$A68,Records!$AB:$AB,"<>Y",Records!$Q:$Q,"Y")
A69: A11 | B69: Migration & the city | C69: =COUNTIFS(Records!$M:$M,$A69,Records!$AB:$AB,"<>Y",Records!$T:$T,C$58) | D69: =COUNTIFS(Records!$M:$M,$A69,Records!$AB:$AB,"<>Y",Records!$T:$T,D$58) | E69: =COUNTIFS(Records!$M:$M,$A69,Records!$AB:$AB,"<>Y",Records!$T:$T,E$58) | F69: =COUNTIFS(Records!$M:$M,$A69,Records!$AB:$AB,"<>Y",Records!$T:$T,F$58) | G69: =COUNTIFS(Records!$M:$M,$A69,Records!$AB:$AB,"<>Y",Records!$T:$T,G$58) | H69: =COUNTIFS(Records!$M:$M,$A69,Records!$AB:$AB,"<>Y",Records!$T:$T,H$58) | I69: =COUNTIFS(Records!$M:$M,$A69,Records!$AB:$AB,"<>Y",Records!$T:$T,I$58) | J69: =COUNTIFS(Records!$M:$M,$A69,Records!$AB:$AB,"<>Y") | K69: =COUNTIFS(Records!$M:$M,$A69,Records!$AB:$AB,"<>Y",Records!$Q:$Q,"Y")
A70: A12 | B70: Gender, caste, class & the city | C70: =COUNTIFS(Records!$M:$M,$A70,Records!$AB:$AB,"<>Y",Records!$T:$T,C$58) | D70: =COUNTIFS(Records!$M:$M,$A70,Records!$AB:$AB,"<>Y",Records!$T:$T,D$58) | E70: =COUNTIFS(Records!$M:$M,$A70,Records!$AB:$AB,"<>Y",Records!$T:$T,E$58) | F70: =COUNTIFS(Records!$M:$M,$A70,Records!$AB:$AB,"<>Y",Records!$T:$T,F$58) | G70: =COUNTIFS(Records!$M:$M,$A70,Records!$AB:$AB,"<>Y",Records!$T:$T,G$58) | H70: =COUNTIFS(Records!$M:$M,$A70,Records!$AB:$AB,"<>Y",Records!$T:$T,H$58) | I70: =COUNTIFS(Records!$M:$M,$A70,Records!$AB:$AB,"<>Y",Records!$T:$T,I$58) | J70: =COUNTIFS(Records!$M:$M,$A70,Records!$AB:$AB,"<>Y") | K70: =COUNTIFS(Records!$M:$M,$A70,Records!$AB:$AB,"<>Y",Records!$Q:$Q,"Y")
... A106: C18 | B106: Neighbourhood platforms & digital public space (WhatsApp, Nextdoor, RWA groups) | C106: =COUNTIFS(Records!$M:$M,$A106,Records!$AB:$AB,"<>Y",Records!$T:$T,C$58) | D106: =COUNTIFS(Records!$M:$M,$A106,Records!$AB:$AB,"<>Y",Records!$T:$T,D$58) | E106: =COUNTIFS(Records!$M:$M,$A106,Records!$AB:$AB,"<>Y",Records!$T:$T,E$58) | F106: =COUNTIFS(Records!$M:$M,$A106,Records!$AB:$AB,"<>Y",Records!$T:$T,F$58) | G106: =COUNTIFS(Records!$M:$M,$A106,Records!$AB:$AB,"<>Y",Records!$T:$T,G$58) | H106: =COUNTIFS(Records!$M:$M,$A106,Records!$AB:$AB,"<>Y",Records!$T:$T,H$58) | I106: =COUNTIFS(Records!$M:$M,$A106,Records!$AB:$AB,"<>Y",Records!$T:$T,I$58) | J106: =COUNTIFS(Records!$M:$M,$A106,Records!$AB:$AB,"<>Y") | K106: =COUNTIFS(Records!$M:$M,$A106,Records!$AB:$AB,"<>Y",Records!$Q:$Q,"Y")
B107: All themes | C107: =SUM(C59:C106) | D107: =SUM(D59:D106) | E107: =SUM(E59:E106) | F107: =SUM(F59:F106) | G107: =SUM(G59:G106) | H107: =SUM(H59:H106) | I107: =SUM(I59:I106) | J107: =SUM(J59:J106) | K107: =SUM(K59:K106)
A110: Theme × period (publication year)
A111: Theme | B111: Name | C111: 2010–14 | D111: 2015–19 | E111: 2020–26 | F111: Before 2010 | G111: Total
A112: A1 | B112: Urban governance, decentralisation & municipal finance | C112: =COUNTIFS(Records!$M:$M,$A112,Records!$AB:$AB,"<>Y",Records!$C:$C,">=2010",Records!$C:$C,"<=2014") | D112: =COUNTIFS(Records!$M:$M,$A112,Records!$AB:$AB,"<>Y",Records!$C:$C,">=2015",Records!$C:$C,"<=2019") | E112: =COUNTIFS(Records!$M:$M,$A112,Records!$AB:$AB,"<>Y",Records!$C:$C,">=2020",Records!$C:$C,"<=2026") | F112: =COUNTIFS(Records!$M:$M,$A112,Records!$AB:$AB,"<>Y",Records!$C:$C,"<2010") | G112: =COUNTIFS(Records!$M:$M,$A112,Records!$AB:$AB,"<>Y")
A113: A2 | B113: Planning, master plans & land-use regulation | C113: =COUNTIFS(Records!$M:$M,$A113,Records!$AB:$AB,"<>Y",Records!$C:$C,">=2010",Records!$C:$C,"<=2014") | D113: =COUNTIFS(Records!$M:$M,$A113,Records!$AB:$AB,"<>Y",Records!$C:$C,">=2015",Records!$C:$C,"<=2019") | E113: =COUNTIFS(Records!$M:$M,$A113,Records!$AB:$AB,"<>Y",Records!$C:$C,">=2020",Records!$C:$C,"<=2026") | F113: =COUNTIFS(Records!$M:$M,$A113,Records!$AB:$AB,"<>Y",Records!$C:$C,"<2010") | G113: =COUNTIFS(Records!$M:$M,$A113,Records!$AB:$AB,"<>Y")
A114: A3 | B114: Housing, informality & slums | C114: =COUNTIFS(Records!$M:$M,$A114,Records!$AB:$AB,"<>Y",Records!$C:$C,">=2010",Records!$C:$C,"<=2014") | D114: =COUNTIFS(Records!$M:$M,$A114,Records!$AB:$AB,"<>Y",Records!$C:$C,">=2015",Records!$C:$C,"<=2019") | E114: =COUNTIFS(Records!$M:$M,$A114,Records!$AB:$AB,"<>Y",Records!$C:$C,">=2020",Records!$C:$C,"<=2026") | F114: =COUNTIFS(Records!$M:$M,$A114,Records!$AB:$AB,"<>Y",Records!$C:$C,"<2010") | G114: =COUNTIFS(Records!$M:$M,$A114,Records!$AB:$AB,"<>Y")
A115: A4 | B115: Eviction, resettlement & displacement | C115: =COUNTIFS(Records!$M:$M,$A115,Records!$AB:$AB,"<>Y",Records!$C:$C,">=2010",Records!$C:$C,"<=2014") | D115: =COUNTIFS(Records!$M:$M,$A115,Records!$AB:$AB,"<>Y",Records!$C:$C,">=2015",Records!$C:$C,"<=2019") | E115: =COUNTIFS(Records!$M:$M,$A115,Records!$AB:$AB,"<>Y",Records!$C:$C,">=2020",Records!$C:$C,"<=2026") | F115: =COUNTIFS(Records!$M:$M,$A115,Records!$AB:$AB,"<>Y",Records!$C:$C,"<2010") | G115: =COUNTIFS(Records!$M:$M,$A115,Records!$AB:$AB,"<>Y")
...

Sheet Growth
A1: Growth — OpenAlex-wide counts per theme (prepared in Stage 2 for the Stage 3 analysis)
A2: Source: scripts/growth_counts.py (data/raw/counts/growth_stage2.json, data/processed/growth_counts.csv). Journal articles and book chapters only (primary location in a journal, book series or ebook platform: repository-only records such as Zenodo are excluded), 2010–2026, each theme's combined query. Counts are multiplied by the theme's estimated precision (random sample of 40 from the full 2015–26 hit set, screened with the theme's rules; borderline counted at the hand keep-rate) and normalised per 10,000 Social Sciences works in the same period under the same filters. 2026 is a partial year (retrieved October 2026); the normalised shares stay comparable because the baseline is equally partial. Growth ratio = normalised share 2020–26 ÷ 2015–19. One precision estimate per theme is applied to both periods.
A4: Theme | B4: Name | C4: Precision est. | D4: Raw 2015–19 | E4: Raw 2020–26 | F4: Adj. per 10k SS 2015–19 | G4: Adj. per 10k SS 2020–26 | H4: Growth ratio | I4: SA raw 2015–19 | J4: SA raw 2020–26 | K4: SA adj. per 10k SA-SS 2015–19 | L4: SA adj. per 10k SA-SS 2020–26 | M4: SA growth ratio | N4: 2026 raw (partial)
A5: A1 | B5: Urban governance, decentralisation & municipal finance | C5: 0.406 | D5: 7489 | E5: 19570 | F5: 3.12 | G5: 5.09 | H5: 1.63 | I5: 725 | J5: 1960 | K5: 16.11 | L5: 17.81 | M5: 1.11 | N5: 3250
A6: A2 | B6: Planning, master plans & land-use regulation | C6: 0.547 | D6: 5441 | E6: 14157 | F6: 3.06 | G6: 4.96 | H6: 1.62 | I6: 223 | J6: 951 | K6: 6.68 | L6: 11.64 | M6: 1.74 | N6: 2607
A7: A3 | B7: Housing, informality & slums | C7: 0.509 | D7: 14671 | E7: 28664 | F7: 7.66 | G7: 9.34 | H7: 1.22 | I7: 2507 | J7: 4567 | K7: 69.8 | L7: 51.99 | M7: 0.74 | N7: 4012
A8: A4 | B8: Eviction, resettlement & displacement | C8: 0.518 | D8: 1997 | E8: 4796 | F8: 1.06 | G8: 1.59 | H8: 1.5 | I8: 248 | J8: 560 | K8: 7.02 | L8: 6.49 | M8: 0.92 | N8: 691
A9: A5 | B9: Land, peri-urban & extended urbanisation | C9: 0.325 | D9: 8487 | E9: 21084 | F9: 2.83 | G9: 4.39 | H9: 1.55 | I9: 995 | J9: 2542 | K9: 17.71 | L9: 18.49 | M9: 1.04 | N9: 4305
A10: A6 | B10: Small towns, census towns & secondary cities | C10: 0.316 | D10: 2328 | E10: 5748 | F10: 0.75 | G10: 1.16 | H10: 1.55 | I10: 215 | J10: 477 | K10: 3.72 | L10: 3.37 | M10: 0.91 | N10: 989
A11: A7 | B11: Urban infrastructure (water, sanitation, energy) & infrastructural citizenship | C11: 0.405 | D11: 3767 | E11: 10091 | F11: 1.57 | G11: 2.62 | H11: 1.67 | I11: 603 | J11: 1571 | K11: 13.37 | L11: 14.24 | M11: 1.07 | N11: 2083
A12: A8 | B12: Mobility & transport (social science) | C12: 0.598 | D12: 1924 | E12: 6064 | F12: 1.18 | G12: 2.32 | H12: 1.97 | I12: 225 | J12: 674 | K12: 7.36 | L12: 9.02 | M12: 1.23 | N12: 1166
A13: A9 | B13: Public space, publicness & the street | C13: 0.416 | D13: 6701 | E13: 16570 | F13: 2.86 | G13: 4.41 | H13: 1.54 | I13: 255 | J13: 765 | K13: 5.8 | L13: 7.12 | M13: 1.23 | N13: 2600
